Workbook
Name A_CF: [1]Annuity!$D$5
Name A_DR: [1]Annuity!$D$7
Name A_NP: [1]Annuity!$D$6
Name D: #REF!
Name D: #REF!
Name D: #REF!
Name D: #REF!
Name D: #REF!
Name D: #REF!
Name D: #REF!
Name D: #REF!
Name D: #REF!
Name GA_CF: '[1]Growing Annuity'!$D$5
Name GA_DR: '[1]Growing Annuity'!$D$8
Name GA_GR: '[1]Growing Annuity'!$D$6
Name GA_NP: '[1]Growing Annuity'!$D$7
Name GP_CF: '[1]Growing Perpetuity'!$D$5
Name GP_DR: '[1]Growing Perpetuity'!$D$7
Name GP_GR: '[1]Growing Perpetuity'!$D$6
Name IRC_NP: #REF!
Name IRC_NP: #REF!
Name IRC_NP: #REF!
Name IRC_NP: #REF!
Name IRC_NP: #REF!
Name IRC_NP: #REF!
Name IRC_NP: #REF!
Name IRC_NP: #REF!
Name IRC_NP: #REF!
Name IRC_NP: #REF!
Name IRC_NP: #REF!
Name IRC_SAIR: #REF!
Name IRC_SAIR: #REF!
Name IRC_SAIR: #REF!
Name IRC_SAIR: #REF!
Name IRC_SAIR: #REF!
Name IRC_SAIR: #REF!
Name IRC_SAIR: #REF!
Name IRC_SAIR: #REF!
Name IRC_SAIR: #REF!
Name IRC_SAIR: #REF!
Name IRC_SAIR: #REF!
Name P_CF: [1]Perpetuity!$D$5
Name P_DR: [1]Perpetuity!$D$6
Name S_CF: '[1]Single Cash Flow'!$D$3
Name S_DR: '[1]Single Cash Flow'!$D$5
Name S_T: '[1]Single Cash Flow'!$D$4

Sheet Table of Content
C3: Table of Content
C5: Data
C6: Excerpts from Aramco's Financial Statements
C7: Excerpts from Chevron's Financial Statements
C8: Excerpts from Exxon's Financial Statements
C9: Excerpts from Oxy's Financial Statements
C10: Exhibit A2: Stock Prices at the End of December 2018-2022 and the Previous Trading Day
C11: Exhibit A3: Dividends and Share Buybacks 2018-2022 and Q1 2023
C12: Exhibit A4: Costs of Equity
C13: Exhibit B1: Aramco's Debt in 2022
C14: Exhibit B4: Term Sheet of Oxy’s 3.500% Senior Unsecured Notes due 2025
C16: Case A: Equity Analysis and Valuation
... C27: Question B9: Cash Deployment in 2022

Sheet Aramco
C3: Excerpts from Aramco's Financial Statements | R3: Return to TOC
C5: Exchange Rate SAR/USD | D5: 3.75
C7: In millions of SAR | D7: 2022 | E7: 2021 | F7: 2020 | G7: 2019 | H7: 2018 | J7: In millions of USD | K7: 2022 | L7: 2021 | M7: 2020 | N7: 2019 | O7: 2018
C8: Income Statement | J8: Income Statement
C9: Revenue | D9: 2266373 | E9: 1501758 | F9: 862091 | G9: 1236785 | H9: 1347017 | J9: Revenue | K9: =D9/$D$5 -> 604366.13 | L9: =E9/$D$5 -> 400468.8 | M9: =F9/$D$5 -> 229890.93 | N9: =G9/$D$5 -> 329809.33 | O9: =H9/$D$5 -> 359204.53
C10: Depreciation and Amortization | D10: 91618 | E10: 85521 | F10: 76208 | G10: 50266 | H10: 41334 | J10: Depreciation and Amortization | K10: =D10/$D$5 -> 24431.467 | L10: =E10/$D$5 -> 22805.6 | M10: =F10/$D$5 -> 20322.133 | N10: =G10/$D$5 -> 13404.267 | O10: =H10/$D$5 -> 11022.4
C11: EBIT | D11: 1144077 | E11: 771918 | F11: 383360 | G11: 674871 | H11: 798405 | J11: EBIT | K11: =D11/$D$5 -> 305087.2 | L11: =E11/$D$5 -> 205844.8 | M11: =F11/$D$5 -> 102229.33 | N11: =G11/$D$5 -> 179965.6 | O11: =H11/$D$5 -> 212908
C12: Interest Expense | D12: 8882 | E12: 12058 | F12: 10564 | G12: 6026 | H12: 2959 | J12: Interest Expense | K12: =D12/$D$5 -> 2368.5333 | L12: =E12/$D$5 -> 3215.4667 | M12: =F12/$D$5 -> 2817.0667 | N12: =G12/$D$5 -> 1606.9333 | O12: =H12/$D$5 -> 789.06667
C13: Interest Income | D13: 14894 | E13: 1787 | F13: 3182 | G13: 7351 | H13: 3865 | J13: Interest Income | K13: =D13/$D$5 -> 3971.7333 | L13: =E13/$D$5 -> 476.53333 | M13: =F13/$D$5 -> 848.53333 | N13: =G13/$D$5 -> 1960.2667 | O13: =H13/$D$5 -> 1030.6667
C14: Net Income | D14: 604005 | E14: 412396 | F14: 183763 | G14: 330693 | H14: 416518 | J14: Net Income | K14: =D14/$D$5 -> 161068 | L14: =E14/$D$5 -> 109972.27 | M14: =F14/$D$5 -> 49003.467 | N14: =G14/$D$5 -> 88184.8 | O14: =H14/$D$5 -> 111071.47
C15: Balance Sheet | J15: Balance Sheet
C16: Cash and Cash Equivalents | D16: 226047 | E16: 299579 | F16: 207232 | G16: 177706 | H16: 183152 | J16: Cash and Cash Equivalents | K16: =D16/$D$5 -> 60279.2 | L16: =E16/$D$5 -> 79887.733 | M16: =F16/$D$5 -> 55261.867 | N16: =G16/$D$5 -> 47388.267 | O16: =H16/$D$5 -> 48840.533
C17: Total Current Assets | D17: 857831 | E17: 611241 | F17: 398879 | G17: 408196 | H17: 383383 | J17: Total Current Assets | K17: =D17/$D$5 -> 228754.93 | L17: =E17/$D$5 -> 162997.6 | M17: =F17/$D$5 -> 106367.73 | N17: =G17/$D$5 -> 108852.27 | O17: =H17/$D$5 -> 102235.47
C18: Total Non-Current Assets | D18: 1635093 | E18: 1551449 | F18: 1515382 | G18: 1085930 | H18: 963509 | J18: Total Non-Current Assets | K18: =D18/$D$5 -> 436024.8 | L18: =E18/$D$5 -> 413719.73 | M18: =F18/$D$5 -> 404101.87 | N18: =G18/$D$5 -> 289581.33 | O18: =H18/$D$5 -> 256935.73
C19: Total Assets | D19: =D17+D18 -> 2492924 | E19: =E17+E18 -> 2162690 | F19: =F17+F18 -> 1914261 | G19: =G17+G18 -> 1494126 | H19: =H17+H18 -> 1346892 | J19: Total Assets | K19: =D19/$D$5 -> 664779.73 | L19: =E19/$D$5 -> 576717.33 | M19: =F19/$D$5 -> 510469.6 | N19: =G19/$D$5 -> 398433.6 | O19: =H19/$D$5 -> 359171.2
C20: Short-Term Debt | D20: 74764 | E20: 74550 | F20: 99157 | G20: 24895 | H20: 29989 | J20: Short-Term Debt | K20: =D20/$D$5 -> 19937.067 | L20: =E20/$D$5 -> 19880 | M20: =F20/$D$5 -> 26441.867 | N20: =G20/$D$5 -> 6638.6667 | O20: =H20/$D$5 -> 7997.0667
C21: Long-Term Debt | D21: 318380 | E21: 436371 | F21: 436920 | G21: 150690 | H21: 71329 | J21: Long-Term Debt | K21: =D21/$D$5 -> 84901.333 | L21: =E21/$D$5 -> 116365.6 | M21: =F21/$D$5 -> 116512 | N21: =G21/$D$5 -> 40184 | O21: =H21/$D$5 -> 19021.067
C22: Total Liabilities | D22: 826777 | E22: 882022 | F22: 813167 | G22: 447891 | H22: 318457 | J22: Total Liabilities | K22: =D22/$D$5 -> 220473.87 | L22: =E22/$D$5 -> 235205.87 | M22: =F22/$D$5 -> 216844.53 | N22: =G22/$D$5 -> 119437.6 | O22: =H22/$D$5 -> 84921.867
C23: Common Stock | D23: 75000 | E23: 60000 | F23: 60000 | G23: 60000 | H23: 60000 | J23: Common Stock | K23: =D23/$D$5 -> 20000 | L23: =E23/$D$5 -> 16000 | M23: =F23/$D$5 -> 16000 | N23: =G23/$D$5 -> 16000 | O23: =H23/$D$5 -> 16000
C24: Additional Paid-In Capital | D24: 26981 | E24: 26981 | F24: 26981 | G24: 26981 | H24: 26981 | J24: Additional Paid-In Capital | K24: =D24/$D$5 -> 7194.9333 | L24: =E24/$D$5 -> 7194.9333 | M24: =F24/$D$5 -> 7194.9333 | N24: =G24/$D$5 -> 7194.9333 | O24: =H24/$D$5 -> 7194.9333
C25: Retained Earnings | D25: 1345892 | E25: 1024443 | F25: 901273 | G25: 949758 | H25: 926625 | J25: Retained Earnings | K25: =D25/$D$5 -> 358904.53 | L25: =E25/$D$5 -> 273184.8 | M25: =F25/$D$5 -> 240339.47 | N25: =G25/$D$5 -> 253268.8 | O25: =H25/$D$5 -> 247100
C26: Treasury Stock | D26: -2236 | E26: -2828 | F26: -3264 | G26: -3750 | H26: 0 | J26: Treasury Stock | K26: =D26/$D$5 -> -596.26667 | L26: =E26/$D$5 -> -754.13333 | M26: =F26/$D$5 -> -870.4 | N26: =G26/$D$5 -> -1000 | O26: =H26/$D$5 -> 0
C27: Total Equity | D27: 1666147 | E27: 1280668 | F27: 1101094 | G27: 1046235 | H27: 1028435 | J27: Total Equity | K27: =D27/$D$5 -> 444305.87 | L27: =E27/$D$5 -> 341511.47 | M27: =F27/$D$5 -> 293625.07 | N27: =G27/$D$5 -> 278996 | O27: =H27/$D$5 -> 274249.33
C28: Cash Flow Statement | J28: Cash Flow Statement
C29: Cash Flow from Operating Activities | D29: 698152 | E29: 522601 | F29: 285297 | G29: 416529 | H29: 453701 | J29: Cash Flow from Operating Activities | K29: =D29/$D$5 -> 186173.87 | L29: =E29/$D$5 -> 139360.27 | M29: =F29/$D$5 -> 76079.2 | N29: =G29/$D$5 -> 111074.4 | O29: =H29/$D$5 -> 120986.93
C30: Capital Expenditure | D30: -141161 | E30: -119645 | F30: -101030 | G30: -122882 | H30: -131766 | J30: Capital Expenditure | K30: =D30/$D$5 -> -37642.933 | L30: =E30/$D$5 -> -31905.333 | M30: =F30/$D$5 -> -26941.333 | N30: =G30/$D$5 -> -32768.533 | O30: =H30/$D$5 -> -35137.6
C31: Cash Flow from Investing Activities | D31: -389009 | E31: -135741 | F31: -20899 | G31: -177144 | H31: -131205 | J31: Cash Flow from Investing Activities | K31: =D31/$D$5 -> -103735.73 | L31: =E31/$D$5 -> -36197.6 | M31: =F31/$D$5 -> -5573.0667 | N31: =G31/$D$5 -> -47238.4 | O31: =H31/$D$5 -> -34988
C32: Proceeds from Issuance of Debt | D32: 9082 | E32: 42213 | F32: 87520 | G32: 51960 | H32: 11660 | J32: Proceeds from Issuance of Debt | K32: =D32/$D$5 -> 2421.8667 | L32: =E32/$D$5 -> 11256.8 | M32: =F32/$D$5 -> 23338.667 | N32: =G32/$D$5 -> 13856 | O32: =H32/$D$5 -> 3109.3333
C33: Repayments of Debt | D33: -132514 | E33: -73563 | F33: -42125 | G33: -5162 | H33: -11096 | J33: Repayments of Debt | K33: =D33/$D$5 -> -35337.067 | L33: =E33/$D$5 -> -19616.8 | M33: =F33/$D$5 -> -11233.333 | N33: =G33/$D$5 -> -1376.5333 | O33: =H33/$D$5 -> -2958.9333
C34: Payment of Dividends | D34: -295735 | E34: -288417 | F34: -261902 | G34: -274424 | H34: -218402 | J34: Payment of Dividends | K34: =D34/$D$5 -> -78862.667 | L34: =E34/$D$5 -> -76911.2 | M34: =F34/$D$5 -> -69840.533 | N34: =G34/$D$5 -> -73179.733 | O34: =H34/$D$5 -> -58240.533
C35: Repurchase of Treasury Stock | D35: 550 | E35: 384 | F35: 0 | G35: -3750 | H35: 0 | J35: Repurchase of Treasury Stock | K35: =D35/$D$5 -> 146.66667 | L35: =E35/$D$5 -> 102.4 | M35: =F35/$D$5 -> 0 | N35: =G35/$D$5 -> -1000 | O35: =H35/$D$5 -> 0
C36: Cash Flow from Financing Activities | D36: -382675 | E36: -294513 | F36: -234872 | G36: -244831 | H36: -220586 | J36: Cash Flow from Financing Activities | K36: =D36/$D$5 -> -102046.67 | L36: =E36/$D$5 -> -78536.8 | M36: =F36/$D$5 -> -62632.533 | N36: =G36/$D$5 -> -65288.267 | O36: =H36/$D$5 -> -58822.933
C37: Other Information
C38: Common Shares Outstanding (million) | D38: 220000 | E38: 200000 | F38: 200000 | G38: 200000 | H38: 200000

Sheet Chevron
C3: Excerpts from Chevron's Financial Statements | K3: Return to TOC
C5: In millions of USD | D5: 2022 | E5: 2021 | F5: 2020 | G5: 2019 | H5: 2018
C6: Income Statement
C7: Revenue | D7: 246252 | E7: 162465 | F7: 94692 | G7: 146516 | H7: 166339
C8: Depreciation and Amortization | D8: 16319 | E8: 17925 | F8: 19508 | G8: 29218 | H8: 19419
C9: EBIT | D9: 54517 | E9: 27002 | F9: -3037 | G9: 10887 | H9: 26750
C10: Interest Expense | D10: 476 | E10: 662 | F10: 658 | G10: 761 | H10: 713
C11: Interest Income | D11: 261 | E11: 36 | F11: 52 | G11: 181 | H11: 137
C12: Net Income | D12: 35608 | E12: 15689 | F12: -5561 | G12: 2845 | H12: 14860
C13: Balance Sheet
C14: Cash and Cash Equivalents | D14: 17678 | E14: 5640 | F14: 5596 | G14: 5686 | H14: 9342
C15: Total Current Assets | D15: 50343 | E15: 33738 | F15: 26078 | G15: 28329 | H15: 34021
C16: Total Non-Current Assets | D16: 207366 | E16: 205797 | F16: 213712 | G16: 209099 | H16: 219842
C17: Total Assets | D17: =D15+D16 -> 257709 | E17: =E15+E16 -> 239535 | F17: =F15+F16 -> 239790 | G17: =G15+G16 -> 237428 | H17: =H15+H16 -> 253863
C18: Short-Term Debt | D18: 1964 | E18: 256 | F18: 1548 | G18: 3282 | H18: 5726
C19: Long-Term Debt | D19: 21375 | E19: 31113 | F19: 42767 | G19: 23691 | H19: 28733
C20: Total Liabilities | D20: 97467 | E20: 99595 | F20: 107064 | G20: 92220 | H20: 98221
C21: Common Stock | D21: 1832 | E21: 1832 | F21: 1832 | G21: 1832 | H21: 1832
C22: Additional Paid-In Capital | D22: 18660 | E22: 17282 | F22: 16829 | G22: 17265 | H22: 17112
C23: Retained Earnings | D23: 190024 | E23: 165546 | F23: 160377 | G23: 174945 | H23: 180987
C24: Treasury Stock | D24: -48196 | E24: -41464 | F24: -41498 | G24: -44599 | H24: -41593
C25: Total Equity | D25: 160242 | E25: 139940 | F25: 132726 | G25: 145208 | H25: 155642
C26: Cash Flow Statement
C27: Cash Flow from Operating Activities | D27: 49602 | E27: 29187 | F27: 10577 | G27: 27314 | H27: 30618
C28: Capital Expenditure | D28: -11974 | E28: -8056 | F28: -8922 | G28: -14116 | H28: -13792
C29: Cash Flow from Investing Activities | D29: -12108 | E29: -5865 | F29: -6965 | G29: -11458 | H29: -12290
C30: Proceeds from Issuance of Debt | D30: 0 | E30: 0 | F30: 12308 | G30: 0 | H30: 218
C31: Repayments of Debt | D31: -8742 | E31: -7364 | F31: -5489 | G31: -5025 | H31: -6741
C32: Payment of Dividends | D32: -10968 | E32: -10179 | F32: -9651 | G32: -8959 | H32: -8502
C33: Repurchase of Treasury Stock | D33: -5417 | E33: 38 | F33: -1531 | G33: -2935 | H33: -604
C34: Cash Flow from Financing Activities | D34: -24978 | E34: -23113 | F34: -3736 | G34: -19758 | H34: -13699
C35: Other Information
C36: Common Shares Outstanding (million) | D36: 1915 | E36: 1930 | F36: 1925 | G36: 1882 | H36: 1903

Sheet Exxon
C3: Excerpts from Exxon's Financial Statements | K3: Return to TOC
C5: In millions of USD | D5: 2022 | E5: 2021 | F5: 2020 | G5: 2019 | H5: 2018
C6: Income Statement
C7: Revenue | D7: 413680 | E7: 285640 | F7: 181502 | G7: 264938 | H7: 290212
C8: Depreciation and Amortization | D8: 24040 | E8: 20607 | F8: 25756 | G8: 18998 | H8: 18745
C9: EBIT | D9: 106952 | E9: 63206 | F9: -398 | G9: 52646 | H9: 65667
C10: Interest Expense | D10: 798 | E10: 947 | F10: 1158 | G10: 830 | H10: 766
C11: Interest Income | D11: 446 | E11: 33 | F11: 49 | G11: 84 | H11: 64
C12: Net Income | D12: 57577 | E12: 23598 | F12: -23251 | G12: 14774 | H12: 21421
C13: Balance Sheet
C14: Cash and Cash Equivalents | D14: 29640 | E14: 6802 | F14: 4364 | G14: 3089 | H14: 3042
C15: Total Current Assets | D15: 97631 | E15: 59154 | F15: 44893 | G15: 50052 | H15: 47973
C16: Total Non-Current Assets | D16: 271436 | E16: 279769 | F16: 287857 | G16: 312545 | H16: 298223
C17: Total Assets | D17: =D15+D16 -> 369067 | E17: =E15+E16 -> 338923 | F17: =F15+F16 -> 332750 | G17: =G15+G16 -> 362597 | H17: =H15+H16 -> 346196
C18: Short-Term Debt | D18: 634 | E18: 4276 | F18: 20458 | G18: 20578 | H18: 17258
C19: Long-Term Debt | D19: 40559 | E19: 43428 | F19: 47182 | G19: 26342 | H19: 20538
C20: Total Liabilities | D20: 166594 | E20: 163240 | F20: 168620 | G20: 163659 | H20: 147668
C21: Common Stock | D21: 15752 | E21: 15746 | F21: 15688 | G21: 15637 | H21: 15258
C22: Retained Earnings | D22: 432860 | E22: 392059 | F22: 383943 | G22: 421341 | H22: 421653
C23: Treasury Stock | D23: -240293 | E23: -225464 | F23: -225776 | G23: -225835 | H23: -225553
C24: Total Equity | D24: 202473 | E24: 175683 | F24: 164130 | G24: 198938 | H24: 198528
C25: Cash Flow Statement
C26: Cash Flow from Operating Activities | D26: 76797 | E26: 48129 | F26: 14668 | G26: 29716 | H26: 36014
C27: Capital Expenditure | D27: -18407 | E27: -12076 | F27: -17282 | G27: -24361 | H27: -19574
C28: Cash Flow from Investing Activities | D28: -14742 | E28: -10235 | F28: -18459 | G28: -23084 | H28: -16446
C29: Proceeds from Issuance of Debt | D29: 860 | E29: 12733 | F29: 59212 | G29: 27030 | H29: 46
C30: Repayments of Debt | D30: -8080 | E30: -32387 | F30: -38441 | G30: -18368 | H30: -4971
C31: Payment of Dividends | D31: -15206 | E31: -15148 | F31: -15053 | G31: -14844 | H31: -14041
C32: Repurchase of Treasury Stock | D32: -15155 | E32: -155 | F32: -405 | G32: -594 | H32: -626
C33: Cash Flow from Financing Activities | D33: -39114 | E33: -35423 | F33: 5285 | G33: -6618 | H33: -19446
C34: Other Information
C35: Common Shares Outstanding (million) | D35: 4082 | E35: 4239 | F35: 4233 | G35: 4234 | H35: 4237

Sheet Oxy
C3: Excerpts from Oxy's Financial Statements | K3: Return to TOC
C5: In millions of USD | D5: 2022 | E5: 2021 | F5: 2020 | G5: 2019 | H5: 2018
C6: Income Statement
C7: Revenue | D7: 37095 | E7: 26314 | F7: 16261 | G7: 21750 | H7: 18934
C8: Depreciation and Amortization | D8: 6926 | E8: 8447 | F8: 8097 | G8: 6140 | H8: 3977
C9: EBIT | D9: 15674 | E9: 6029 | F9: -2184 | G9: 4662 | H9: 6666
C10: Interest Expense | D10: 1030 | E10: 1614 | F10: 1424 | G10: 1066 | H10: 389
C11: Interest Income | D11: 153 | E11: 166 | F11: 118 | G11: 217 | H11: 136
C12: Net Income | D12: 13304 | E12: 2322 | F12: -14831 | G12: -522 | H12: 4131
C13: Balance Sheet
C14: Cash and Cash Equivalents | D14: 984 | E14: 2764 | F14: 2008 | G14: 3032 | H14: 3033
C15: Total Current Assets | D15: 8886 | E15: 10211 | F15: 8819 | G15: 14633 | H15: 9932
C16: Total Non-Current Assets | D16: 63723 | E16: 64825 | F16: 71245 | G16: 92557 | H16: 33922
C17: Total Assets | D17: =D15+D16 -> 72609 | E17: =E15+E16 -> 75036 | F17: =F15+F16 -> 80064 | G17: =G15+G16 -> 107190 | H17: =H15+H16 -> 43854
C18: Short-Term Debt | D18: 165 | E18: 186 | F18: 440 | G18: 51 | H18: 116
C19: Long-Term Debt | D19: 19670 | E19: 29431 | F19: 35745 | G19: 38537 | H19: 10201
C20: Total Liabilities | D20: 42524 | E20: 54709 | F20: 61491 | G20: 72958 | H20: 22524
C21: Preferred Stock | D21: 9762 | E21: 9762 | F21: 9762 | G21: 9762 | H21: 0
C22: Common Stock | D22: 220 | E22: 217 | F22: 216 | G22: 209 | H22: 179
C23: Additional Paid-In Capital | D23: 17181 | E23: 16749 | F23: 16552 | G23: 14955 | H23: 8046
C24: Retained Earnings | D24: 16499 | E24: 4480 | F24: 2996 | G24: 20180 | H24: 23750
C25: Treasury Stock | D25: -13772 | E25: -10673 | F25: -10665 | G25: -10653 | H25: -10473
C26: Total Equity | D26: 30085 | E26: 20327 | F26: 18573 | G26: 34232 | H26: 21330
C27: Cash Flow Statement
C28: Cash Flow from Operating Activities | D28: 16810 | E28: 10434 | F28: 3955 | G28: 7375 | H28: 7669
C29: Capital Expenditure | D29: -4497 | E29: -2870 | F29: -2535 | G29: -6367 | H29: -4975
C30: Cash Flow from Investing Activities | D30: -4872 | E30: -1253 | F30: -819 | G30: -29027 | H30: -3206
C31: Proceeds from Issuance of Debt | D31: 0 | E31: 0 | F31: 6936 | G31: 22016 | H31: 978
C32: Repayments of Debt | D32: -9484 | E32: -6834 | F32: -8916 | G32: -6959 | H32: -500
C33: Payment of Preferred Dividends | D33: -800 | E33: -800 | F33: -844 | G33: -318 | H33: 0
C34: Payment of Common Dividends | D34: -384 | E34: -39 | F34: -1001 | G34: -2306 | H34: -2374
C35: Repurchase of Treasury Stock | D35: -3099 | E35: -8 | F35: -12 | G35: -237 | H35: -1248
C36: Cash Flow from Financing Activities | D36: -13715 | E36: -8572 | F36: -4516 | G36: 22193 | H36: -3102
C37: Other Information
C38: Preferred Shares Outstanding (thousand) | D38: 100 | E38: 100 | F38: 100 | G38: 100 | H38: 0
C39: Common Shares Outstanding (million) | D39: 900 | E39: 934 | F39: 932 | G39: 894 | H39: 749

Sheet Exhibit A2
C3: Exhibit A2: Stock Prices at the End of December 2018-2022 and the Previous Trading Day | J3: Return to TOC
D5: Aramco | E5: Chevron | F5: Exxon | G5: Oxy
C6: 31 March 2023 | D6: 29.36 | E6: 163.16 | F6: 109.66 | G6: 62.43
C7: 29 or 30 December 2022 | D7: 29.18 | E7: 179.49 | F7: 110.3 | G7: 62.99
C8: 30 or 31 December 2021 | D8: 29.59 | E8: 117.35 | F8: 61.19 | G8: 28.99
C9: 31 December 2020 | D9: 28.93 | E9: 84.45 | F9: 41.22 | G9: 17.31
C10: 31 December 2019 | D10: 26.48 | E10: 120.51 | F10: 69.78 | G10: 41.21
C11: 31 December 2018 | E11: 108.79 | F11: 68.19 | G11: 61.38

Sheet Exhibit A3
C3: Exhibit A3: Dividends and Share Buybacks 2018-2022 and Q1 2023 | K3: Return to TOC
E5: Aramco | F5: Chevron | G5: Exxon | H5: Oxy
C7: Q1 2023 | D7: Common Dividend per Share | E7: 0.33 | F7: 1.51 | G7: 0.91 | H7: 0.13
C9: 2022 | D9: Net Income ($m) | E9: 161068 | F9: 35608 | G9: 57577 | H9: 13304
D10: Preferred Dividend ($m) | H10: 800
D11: Common Dividends ($m) | E11: 78862.667 | F11: 10968 | G11: 15206 | H11: 384
D12: Share Buybacks ($m) | E12: 596.26667 | F12: 5417 | G12: 15155 | H12: 3099
D13: Earnings per Share ($) | E13: 0.73212727 | F13: 18.594256 | G13: 14.105096 | H13: 14.782222
D14: Common Dividend per Share ($) | E14: 0.35846667 | F14: 5.7274151 | G14: 3.7251347 | H14: 0.42666667
C16: 2021 | D16: Net Income ($m) | E16: 109972.27 | F16: 15689 | G16: 23598 | H16: 2322
D17: Preferred Dividend ($m) | H17: 800
D18: Common Dividends ($m) | E18: 76911.2 | F18: 10179 | G18: 15148 | H18: 39
D19: Share Buybacks ($m) | E19: 754.13333 | F19: -38 | G19: 155 | H19: 8
D20: Earnings per Share ($) | E20: 0.54986133 | F20: 8.1290155 | G20: 5.566879 | H20: 2.4860814
D21: Common Dividend per Share ($) | E21: 0.384556 | F21: 5.2740933 | G21: 3.5734843 | H21: 0.041755889
C23: 2020 | D23: Net Income ($m) | E23: 49003.467 | F23: -5561 | G23: -23251 | H23: -14831
D24: Preferred Dividend ($m) | H24: 844
D25: Common Dividends ($m) | E25: 69840.533 | F25: 9651 | G25: 15053 | H25: 1001
D26: Share Buybacks ($m) | E26: 870.4 | F26: 1531 | G26: 405 | H26: 12
D27: Earnings per Share ($) | E27: 0.24501733 | F27: -2.8888312 | G27: -5.4927947 | H27: -15.91309
D28: Common Dividend per Share ($) | E28: 0.34920267 | F28: 5.0135065 | G28: 3.5561068 | H28: 1.0740343
C30: 2019 | D30: Net Income ($m) | E30: 88184.8 | F30: 2845 | G30: 14774 | H30: -522
D31: Preferred Dividend ($m) | H31: 318
D32: Common Dividends ($m) | E32: 73179.733 | F32: 8959 | G32: 14844 | H32: 2306
D33: Share Buybacks ($m) | E33: 1000 | F33: 2935 | G33: 594 | H33: 237
D34: Earnings per Share ($) | E34: 0.440924 | F34: 1.5116897 | G34: 3.4893718 | H34: -0.58389262
D35: Common Dividend per Share ($) | E35: 0.36589867 | F35: 4.7603613 | G35: 3.5059046 | H35: 2.5794183
C37: 2018 | D37: Net Income ($m) | E37: 111071.47 | F37: 14860 | G37: 21421 | H37: 4131
D38: Preferred Dividend ($m) | H38: 0
D39: Common Dividends ($m) | E39: 58240.533 | F39: 8502 | G39: 14041 | H39: 2374
D40: Share Buybacks ($m) | E40: 0 | F40: 604 | G40: 626 | H40: 1248
D41: Earnings per Share ($) | E41: 0.55535733 | F41: 7.8087231 | G41: 5.0556998 | H41: 5.5153538
D42: Common Dividend per Share ($) | E42: 0.29120267 | F42: 4.4676826 | G42: 3.3139013 | H42: 3.1695594

Sheet Exhibit A4
C3: Exhibit A4: Costs of Equity | J3: Return to TOC
D5: Aramco | E5: Chevron | F5: Exxon | G5: Oxy
C6: Cost of Equity | D6: 0.113 | E6: 0.108 | F6: 0.103 | G6: 0.14

Sheet Exhibit B1
C3: Exhibit B1: Aramco's Debt in 2022 | N3: Return to TOC
E5: Currency | G5: Facility (in millions of SAR) | I5: Balance on 31 December 2022 (in millions of SAR) | K5: Maturity Date
C6: Conventional
C7: Deferred Considerations | E7: SAR | G7: 122163 | I7: 122163 | K7: 2028
C8: Debentures | E8: USD and KRW | G8: 97212 | I8: 97212 | K8: 2023-2070
C9: Bank Borrowings | E9: SAR | G9: 25423 | I9: 23164 | K9: 2023-2045
C10: Short-Term Borrowings | E10: SAR | G10: 27000 | I10: 10205 | K10: 2023
C11: Revolving Credit Facilities | E11: SAR and USD | G11: 47708 | I11: 0 | K11: 2023-2027
C12: Export Credit Agencies | G12: 2239 | I12: 2239 | K12: 2025
C13: Public Investment Fund (PIF) | E13: SAR | G13: 1185 | I13: 1185 | K13: 2025
C14: Other Financing Arrangements | E14: SAR | G14: 23978 | I14: 23978 | K14: 2028-2046
C15: Sharia Compliant
C16: Sukuk | E16: SAR and USD | G16: 34581 | I16: 34581 | K16: 2024-2031
C17: Murabaha | E17: SAR | G17: 28173 | I17: 18293 | K17: 2028-2032
C18: Saudi Industrial Development Fund | E18: SAR | G18: 3784 | I18: 3736 | K18: 2025-2035
C19: Ijarah | E19: SAR | G19: 3304 | I19: 2701 | K19: 2026-2039
C20: Wakala | E20: SAR | G20: 1294 | I20: 1023 | K20: 2028-2036

Sheet Exhibit B4
C3: Exhibit B4: Term Sheet | G3: Return to TOC
C5: Oxy's Note
C6: ISIN | D6: US674599CG82
C7: Issue Date | D7: 42178
C8: Maturity Date | D8: 45823
C9: Issue Volume | D9: 750000000
C10: Denomination | D10: 1000
C11: Coupon Rate | D11: 0.035
C12: Frequency of Coupon Payments per Year | D12: 2
C14: Benchmark U.S. Treasury Note
C15: Maturity Date | D15: 45792
C16: Coupon Rate | D16: 0.02125
C17: Yield to Maturity | D17: 0.02361
C19: Credit Spread on Oxy's Note | D19: =D11-D17 -> 0.01139

Sheet Questions A4 and A6
C3: Question A4: Dividend Yields | R3: Return to TOC
C5: Aramco | J5: Exxon
D7: 2022 | E7: 2021 | F7: 2020 | G7: 2019 | H7: 2018 | K7: 2022 | L7: 2021 | M7: 2020 | N7: 2019 | O7: 2018
C9: Common Dividend per Share | D9: ='Exhibit A3'!E14 -> 0.35846667 | E9: ='Exhibit A3'!E21 -> 0.384556 | F9: ='Exhibit A3'!E28 -> 0.34920267 | G9: ='Exhibit A3'!E35 -> 0.36589867 | H9: n/a | J9: Common Dividend per Share | K9: ='Exhibit A3'!G14 -> 3.7251347 | L9: ='Exhibit A3'!G21 -> 3.5734843 | M9: ='Exhibit A3'!G28 -> 3.5561068 | N9: ='Exhibit A3'!G35 -> 3.5059046 | O9: ='Exhibit A3'!G42 -> 3.3139013
C10: Stock Price at the End of the Year | D10: ='Exhibit A2'!D7/Aramco!$D$5 -> 7.7813333 | E10: ='Exhibit A2'!D8/Aramco!$D$5 -> 7.8906667 | F10: ='Exhibit A2'!D9/Aramco!$D$5 -> 7.7146667 | G10: ='Exhibit A2'!D10/Aramco!$D$5 -> 7.0613333 | H10: n/a | J10: Stock Price at the End of the Year | K10: ='Exhibit A2'!F7 -> 110.3 | L10: ='Exhibit A2'!F8 -> 61.19 | M10: ='Exhibit A2'!F9 -> 41.22 | N10: ='Exhibit A2'!F10 -> 69.78 | O10: ='Exhibit A2'!F11 -> 68.19
C11: Dividend Yield | D11: =D9/D10 -> 0.046067512 | E11: =E9/E10 -> 0.048735553 | F11: =F9/F10 -> 0.045264777 | G11: =G9/G10 -> 0.051817221 | H11: n/a | J11: Dividend Yield | K11: =K9/K10 -> 0.033772754 | L11: =L9/L10 -> 0.058399809 | M11: =M9/M10 -> 0.086271392 | N11: =N9/N10 -> 0.050242255 | O11: =O9/O10 -> 0.048598055
C13: Chevron | J13: Oxy
D15: 2022 | E15: 2021 | F15: 2020 | G15: 2019 | H15: 2018 | K15: 2022 | L15: 2021 | M15: 2020 | N15: 2019 | O15: 2018
C17: Common Dividend per Share | D17: ='Exhibit A3'!F14 -> 5.7274151 | E17: ='Exhibit A3'!F21 -> 5.2740933 | F17: ='Exhibit A3'!F28 -> 5.0135065 | G17: ='Exhibit A3'!F35 -> 4.7603613 | H17: ='Exhibit A3'!F42 -> 4.4676826 | J17: Common Dividend per Share | K17: ='Exhibit A3'!H14 -> 0.42666667 | L17: ='Exhibit A3'!H21 -> 0.041755889 | M17: ='Exhibit A3'!H28 -> 1.0740343 | N17: ='Exhibit A3'!H35 -> 2.5794183 | O17: ='Exhibit A3'!H42 -> 3.1695594
C18: Stock Price at the End of the Year | D18: ='Exhibit A2'!E7 -> 179.49 | E18: ='Exhibit A2'!E8 -> 117.35 | F18: ='Exhibit A2'!E9 -> 84.45 | G18: ='Exhibit A2'!E10 -> 120.51 | H18: ='Exhibit A2'!E11 -> 108.79 | J18: Stock Price at the End of the Year | K18: ='Exhibit A2'!G7 -> 62.99 | L18: ='Exhibit A2'!G8 -> 28.99 | M18: ='Exhibit A2'!G9 -> 17.31 | N18: ='Exhibit A2'!G10 -> 41.21 | O18: ='Exhibit A2'!G11 -> 61.38
C19: Dividend Yield | D19: =D17/D18 -> 0.031909383 | E19: =E17/E18 -> 0.044943275 | F19: =F17/F18 -> 0.059366566 | G19: =G17/G18 -> 0.039501795 | H19: =H17/H18 -> 0.041067034 | J19: Dividend Yield | K19: =K17/K18 -> 0.0067735619 | L19: =L17/L18 -> 0.0014403549 | M19: =M17/M18 -> 0.062047044 | N19: =N17/N18 -> 0.062592049 | O19: =O17/O18 -> 0.051638309
C23: Question A6: Dividend Payout Ratios
C25: Aramco | J25: Exxon
D27: 2022 | E27: 2021 | F27: 2020 | G27: 2019 | H27: 2018 | K27: 2022 | L27: 2021 | M27: 2020 | N27: 2019 | O27: 2018
C29: Common Dividend per Share | D29: =D9 -> 0.35846667 | E29: =E9 -> 0.384556 | F29: =F9 -> 0.34920267 | G29: =G9 -> 0.36589867 | H29: ='Exhibit A3'!E42 -> 0.29120267 | J29: Common Dividend per Share | K29: =K9 -> 3.7251347 | L29: =L9 -> 3.5734843 | M29: =M9 -> 3.5561068 | N29: =N9 -> 3.5059046 | O29: =O9 -> 3.3139013
C30: Earnings per Share | D30: ='Exhibit A3'!E13 -> 0.73212727 | E30: ='Exhibit A3'!E20 -> 0.54986133 | F30: ='Exhibit A3'!E27 -> 0.24501733 | G30: ='Exhibit A3'!E34 -> 0.440924 | H30: ='Exhibit A3'!E41 -> 0.55535733 | J30: Earnings per Share | K30: ='Exhibit A3'!G13 -> 14.105096 | L30: ='Exhibit A3'!G20 -> 5.566879 | M30: ='Exhibit A3'!G27 -> -5.4927947 | N30: ='Exhibit A3'!G34 -> 3.4893718 | O30: ='Exhibit A3'!G41 -> 5.0556998
C31: Dividend Payout Ratio | D31: =D29/D30 -> 0.48962343 | E31: =E29/E30 -> 0.69936905 | F31: =F29/F30 -> 1.4252162 | G31: =G29/G30 -> 0.8298452 | H31: =H29/H30 -> 0.52435189 | J31: Dividend Payout Ratio | K31: =K29/K30 -> 0.26409851 | L31: =L29/L30 -> 0.64191881 | M31: =M29/M30 -> -0.64741301 | N31: =N29/N30 -> 1.0047381 | O31: =O29/O30 -> 0.65547827
C33: Chevron | J33: Oxy
D35: 2022 | E35: 2021 | F35: 2020 | G35: 2019 | H35: 2018 | K35: 2022 | L35: 2021 | M35: 2020 | N35: 2019 | O35: 2018
C37: Common Dividend per Share | D37: =D17 -> 5.7274151 | E37: =E17 -> 5.2740933 | F37: =F17 -> 5.0135065 | G37: =G17 -> 4.7603613 | H37: =H17 -> 4.4676826 | J37: Common Dividend per Share | K37: =K17 -> 0.42666667 | L37: =L17 -> 0.041755889 | M37: =M17 -> 1.0740343 | N37: =N17 -> 2.5794183 | O37: =O17 -> 3.1695594
C38: Earnings per Share | D38: ='Exhibit A3'!F13 -> 18.594256 | E38: ='Exhibit A3'!F20 -> 8.1290155 | F38: ='Exhibit A3'!F27 -> -2.8888312 | G38: ='Exhibit A3'!F34 -> 1.5116897 | H38: ='Exhibit A3'!F41 -> 7.8087231 | J38: Earnings per Share | K38: ='Exhibit A3'!H13 -> 14.782222 | L38: ='Exhibit A3'!H20 -> 2.4860814 | M38: ='Exhibit A3'!H27 -> -15.91309 | N38: ='Exhibit A3'!H34 -> -0.58389262 | O38: ='Exhibit A3'!H41 -> 5.5153538
C39: Dividend Payout Ratio | D39: =D37/D38 -> 0.30802067 | E39: =E37/E38 -> 0.64879852 | F39: =F37/F38 -> -1.7354792 | G39: =G37/G38 -> 3.1490334 | H39: =H37/H38 -> 0.57213997 | J39: Dividend Payout Ratio | K39: =K37/K38 -> 0.0288635 | L39: =L37/L38 -> 0.016795866 | M39: =M37/M38 -> -0.067493763 | N39: =N37/N38 -> -4.4176245 | O39: =O37/O38 -> 0.57467925

Sheet Question A5
C3: Question A5: Total Shareholder Returns | R3: Return to TOC
C5: Aramco | J5: Exxon
D7: 2022 | E7: 2021 | F7: 2020 | G7: 2019 | H7: Average | K7: 2022 | L7: 2021 | M7: 2020 | N7: 2019 | O7: Average
C9: Common Dividend per Share | D9: ='Exhibit A3'!E14 -> 0.35846667 | E9: ='Exhibit A3'!E21 -> 0.384556 | F9: ='Exhibit A3'!E28 -> 0.34920267 | G9: n/a | J9: Common Dividend per Share | K9: ='Exhibit A3'!G14 -> 3.7251347 | L9: ='Exhibit A3'!G21 -> 3.5734843 | M9: ='Exhibit A3'!G28 -> 3.5561068 | N9: ='Exhibit A3'!G35 -> 3.5059046
C10: Stock Price at the Start of the Year | D10: =E11 -> 7.8906667 | E10: =F11 -> 7.7146667 | F10: ='Exhibit A2'!D10/Aramco!D5 -> 7.0613333 | G10: n/a | J10: Stock Price at the Start of the Year | K10: =L11 -> 61.19 | L10: =M11 -> 41.22 | M10: =N11 -> 69.78 | N10: ='Exhibit A2'!F11 -> 68.19
C11: Stock Price at the End of the Year | D11: ='Exhibit A2'!D7/Aramco!D5 -> 7.7813333 | E11: ='Exhibit A2'!D8/Aramco!D5 -> 7.8906667 | F11: ='Exhibit A2'!D9/Aramco!D5 -> 7.7146667 | G11: n/a | J11: Stock Price at the End of the Year | K11: ='Exhibit A2'!F7 -> 110.3 | L11: ='Exhibit A2'!F8 -> 61.19 | M11: ='Exhibit A2'!F9 -> 41.22 | N11: ='Exhibit A2'!F10 -> 69.78
C12: TSR | D12: =(D11-D10+D9)/D10 -> 0.031573167 | E12: =(E11-E10+E9)/E10 -> 0.072661078 | F12: =(F11-F10+F9)/F10 -> 0.14197545 | G12: n/a | H12: =AVERAGE(D12:F12) -> 0.082069899 | J12: TSR | K12: =(K11-K10+K9)/K10 -> 0.86346028 | L12: =(L11-L10+L9)/L10 -> 0.57116653 | M12: =(M11-M10+M9)/M10 -> -0.35832464 | N12: =(N11-N10+N9)/N10 -> 0.074730966 | O12: =AVERAGE(K12:N12) -> 0.28775829
C14: Chevron | J14: Oxy
D16: 2022 | E16: 2021 | F16: 2020 | G16: 2019 | H16: Average | K16: 2022 | L16: 2021 | M16: 2020 | N16: 2019 | O16: Average
C18: Common Dividend per Share | D18: ='Exhibit A3'!F14 -> 5.7274151 | E18: ='Exhibit A3'!F21 -> 5.2740933 | F18: ='Exhibit A3'!F28 -> 5.0135065 | G18: ='Exhibit A3'!F35 -> 4.7603613 | J18: Common Dividend per Share | K18: ='Exhibit A3'!H14 -> 0.42666667 | L18: ='Exhibit A3'!H21 -> 0.041755889 | M18: ='Exhibit A3'!H28 -> 1.0740343 | N18: ='Exhibit A3'!H35 -> 2.5794183
C19: Stock Price at the Start of the Year | D19: =E20 -> 117.35 | E19: =F20 -> 84.45 | F19: =G20 -> 120.51 | G19: ='Exhibit A2'!E11 -> 108.79 | J19: Stock Price at the Start of the Year | K19: =L20 -> 28.99 | L19: =M20 -> 17.31 | M19: =N20 -> 41.21 | N19: ='Exhibit A2'!G11 -> 61.38
C20: Stock Price at the End of the Year | D20: ='Exhibit A2'!E7 -> 179.49 | E20: ='Exhibit A2'!E8 -> 117.35 | F20: ='Exhibit A2'!E9 -> 84.45 | G20: ='Exhibit A2'!E10 -> 120.51 | J20: Stock Price at the End of the Year | K20: ='Exhibit A2'!G7 -> 62.99 | L20: ='Exhibit A2'!G8 -> 28.99 | M20: ='Exhibit A2'!G9 -> 17.31 | N20: ='Exhibit A2'!G10 -> 41.21
C21: TSR | D21: =(D20-D19+D18)/D19 -> 0.57833332 | E21: =(E20-E19+E18)/E19 -> 0.45203189 | F21: =(F20-F19+F18)/F19 -> -0.25762587 | G21: =(G20-G19+G18)/G19 -> 0.15148783 | H21: =AVERAGE(D21:G21) -> 0.23105679 | J21: TSR | K21: =(K20-K19+K18)/K19 -> 1.1875359 | L21: =(L20-L19+L18)/L19 -> 0.67716672 | M21: =(M20-M19+M18)/M19 -> -0.55389385 | N21: =(N20-N19+N18)/N19 -> -0.28658491 | O21: =AVERAGE(K21:N21) -> 0.25605597

Sheet Question A7
C3: Question A7: Book Values and Market Values of Equity | J3: Return to TOC
D5: Aramco | E5: Chevron | F5: Exxon | G5: Oxy
C7: Book Value of Equity (BVE) ($ million) | D7: =Aramco!K27 -> 444305.87 | E7: =Chevron!D25 -> 160242 | F7: =Exxon!D24 -> 202473 | G7: =Oxy!D26 -> 30085
C9: Stock Price 31 March 2023 | D9: ='Exhibit A2'!D6/Aramco!D5 -> 7.8293333 | E9: ='Exhibit A2'!E6 -> 163.16 | F9: ='Exhibit A2'!F6 -> 109.66 | G9: ='Exhibit A2'!G6 -> 62.43
C10: Common Shares Outstanding (million) | D10: =Aramco!D38 -> 220000 | E10: =Chevron!D36 -> 1915 | F10: =Exxon!D35 -> 4082 | G10: =Oxy!D39 -> 900
C11: Market Value of Equity (MVE) ($ million) | D11: =D9*D10 -> 1722453.3 | E11: =E9*E10 -> 312451.4 | F11: =F9*F10 -> 447632.12 | G11: =G9*G10 -> 56187
C13: MVE/BVE | D13: =D11/D7 -> 3.8767288 | E13: =E11/E7 -> 1.9498721 | F13: =F11/F7 -> 2.2108238 | G13: =G11/G7 -> 1.8676084

Sheet Questions A8 and A9
C3: Valuation with the Dividend Discount Model | N3: Interest Rate Conversions | W3: Return to TOC
C5: Question A8: Zero-Growth Model | N5: Cost of Equity Conversions: EAIR to Periodical
E7: Aramco | F7: Chevron | G7: Exxon | H7: Oxy | P7: Aramco | Q7: Chevron | R7: Exxon | S7: Oxy
D9: Quarterly Common Dividend per Share Q1 2023 | E9: ='Exhibit A3'!E7/Aramco!D5 -> 0.088 | F9: ='Exhibit A3'!F7 -> 1.51 | G9: ='Exhibit A3'!G7 -> 0.91 | H9: ='Exhibit A3'!H7 -> 0.13 | O9: (Effective) Annual Cost of Equity | P9: ='Exhibit A4'!D6 -> 0.113 | Q9: ='Exhibit A4'!E6 -> 0.108 | R9: ='Exhibit A4'!F6 -> 0.103 | S9: ='Exhibit A4'!G6 -> 0.14
D10: Quarterly Cost of Equity | E10: =P12 -> 0.027126161 | F10: =Q12 -> 0.025970657 | G10: =R12 -> 0.024811235 | H10: =S12 -> 0.033299485 | O10: Number of Payments per Year | P10: 4 | Q10: 4 | R10: 4 | S10: 4
D11: Implied Stock Price (ISP) | E11: =E9/E10 -> 3.2441007 | F11: =F9/F10 -> 58.142541 | G11: =G9/G10 -> 36.676932 | H11: =H9/H10 -> 3.9039643
O12: Quarterly Cost of Equity | P12: =(1+P9)^(1/P10)-1 -> 0.027126161 | Q12: =(1+Q9)^(1/Q10)-1 -> 0.025970657 | R12: =(1+R9)^(1/R10)-1 -> 0.024811235 | S12: =(1+S9)^(1/S10)-1 -> 0.033299485
D13: Stock Price 31 March 2023 (SP) | E13: ='Exhibit A2'!D6/Aramco!D5 -> 7.8293333 | F13: ='Exhibit A2'!E6 -> 163.16 | G13: ='Exhibit A2'!F6 -> 109.66 | H13: ='Exhibit A2'!G6 -> 62.43
D15: SP/ISP | E15: =E13/E11 -> 2.4134064 | F15: =F13/F11 -> 2.8062069 | G15: =G13/G11 -> 2.9898902 | H15: =H13/H11 -> 15.991437
C18: Question A9: Constant-Growth Model | N18: Dividend Growth Rate Conversions: Periodical to EAIR
E20: Aramco | F20: Chevron | G20: Exxon | H20: Oxy | P20: Aramco | Q20: Chevron | R20: Exxon | S20: Oxy
D22: Quarterly Common Dividend per Share Q1 2023 | E22: =E9 -> 0.088 | F22: =F9 -> 1.51 | G22: =G9 -> 0.91 | H22: =H9 -> 0.13 | O22: Quarterly Dividend Growth Rate | P22: =E23 -> 0.015709387 | Q22: =F23 -> 0.016562617 | R22: =G23 -> 0.016376958 | S22: =H23 -> 0.031152284
D23: Quarterly Dividend Growth Rate | E23: 0.015709387 | F23: 0.016562617 | G23: 0.016376958 | H23: 0.031152284 | O23: Number of Payments per Year | P23: 4 | Q23: 4 | R23: 4 | S23: 4
D24: Quarterly Common Dividend per Share Q2 2023 | E24: =E22*(1+E23) -> 0.089382426 | F24: =F22*(1+F23) -> 1.5350096 | G24: =G22*(1+G23) -> 0.92490303 | H24: =H22*(1+H23) -> 0.1340498
D25: Quarterly Cost of Equity | E25: =P12 -> 0.027126161 | F25: =Q12 -> 0.025970657 | G25: =R12 -> 0.024811235 | H25: =S12 -> 0.033299485 | O25: Effective Annual Dividend Growth Rate | P25: =(1+P22)^P23-1 -> 0.064333825 | Q25: =(1+Q22)^Q23-1 -> 0.067914639 | R25: =(1+R22)^R23-1 -> 0.067134701 | S25: =(1+S22)^S23-1 -> 0.13055379
D26: Implied Stock Price (ISP) | E26: =E24/(E25-E23) -> 7.8290435 | F26: =F24/(F25-F23) -> 163.15933 | G26: =G24/(G25-G23) -> 109.66002 | H26: =H24/(H25-H23) -> 62.430014
D28: Expected Annual Dividend Growth Rate | E28: =P25 -> 0.064333825 | F28: =Q25 -> 0.067914639 | G28: =R25 -> 0.067134701 | H28: =S25 -> 0.13055379

Sheet Questions A10 and A11
C3: Valuation with the Multiples | L3: Return to TOC
C5: Question A10: Price to Earnings (P/E) Ratio
E7: Aramco | F7: Chevron | G7: Exxon | H7: Oxy
D9: Stock Price 31 March 2023 | E9: ='Exhibit A2'!D6/Aramco!D5 -> 7.8293333 | F9: ='Exhibit A2'!E6 -> 163.16 | G9: ='Exhibit A2'!F6 -> 109.66 | H9: ='Exhibit A2'!G6 -> 62.43
D11: Net Income ($ million) | E11: =Aramco!K14 -> 161068 | F11: =Chevron!D12 -> 35608 | G11: =Exxon!D12 -> 57577 | H11: =Oxy!D12 -> 13304
D12: Common Shares Outstanding (million) | E12: =Aramco!D38 -> 220000 | F12: =Chevron!D36 -> 1915 | G12: =Exxon!D35 -> 4082 | H12: =Oxy!D39 -> 900
D13: Earnings per Share (EPS) | E13: =E11/E12 -> 0.73212727 | F13: =F11/F12 -> 18.594256 | G13: =G11/G12 -> 14.105096 | H13: =H11/H12 -> 14.782222
D15: P/E Ratio | E15: =E9/E13 -> 10.693951 | F15: =F9/F13 -> 8.7747529 | G15: =G9/G13 -> 7.7744954 | H15: =H9/H13 -> 4.2233163
C18: Question A11: Enterprise Value to EBITDA Ratio
E20: Aramco | F20: Chevron | G20: Exxon | H20: Oxy
D22: Market Capitalization ($ million) | E22: ='Question A7'!D11 -> 1722453.3 | F22: ='Question A7'!E11 -> 312451.4 | G22: ='Question A7'!F11 -> 447632.12 | H22: ='Question A7'!G11 -> 56187
D23: Total Interest-Bearing Debt ($ million) | E23: =Aramco!K20+Aramco!K21 -> 104838.4 | F23: =Chevron!D18+Chevron!D19 -> 23339 | G23: =Exxon!D18+Exxon!D19 -> 41193 | H23: =Oxy!D18+Oxy!D19 -> 19835
D24: Cash and Cash Equivalents ($ million) | E24: =Aramco!K16 -> 60279.2 | F24: =Chevron!D14 -> 17678 | G24: =Exxon!D14 -> 29640 | H24: =Oxy!D14 -> 984
D25: Enterprise Value ($ million) | E25: =E22+E23-E24 -> 1767012.5 | F25: =F22+F23-F24 -> 318112.4 | G25: =G22+G23-G24 -> 459185.12 | H25: =H22+H23-H24 -> 75038
D27: EBIT ($ million) | E27: =Aramco!K11 -> 305087.2 | F27: =Chevron!D9 -> 54517 | G27: =Exxon!D9 -> 106952 | H27: =Oxy!D9 -> 15674
D28: Depreciation and Amortization ($ million) | E28: =Aramco!K10 -> 24431.467 | F28: =Chevron!D8 -> 16319 | G28: =Exxon!D8 -> 24040 | H28: =Oxy!D8 -> 6926
D29: EBITDA ($ million) | E29: =E27+E28 -> 329518.67 | F29: =F27+F28 -> 70836 | G29: =G27+G28 -> 130992 | H29: =H27+H28 -> 22600
D31: EV/EBITDA Ratio | E31: =E25/E29 -> 5.362405 | F31: =F25/F29 -> 4.4908295 | G31: =G25/G29 -> 3.505444 | H31: =H25/H29 -> 3.3202655

Sheet Question B3
C3: Question B3: Credit Ratios | T3: Return to TOC
C5: Operating Profit Margin
D7: Aramco | K7: Exxon
E9: 2022 | F9: 2021 | G9: 2020 | H9: 2019 | I9: 2018 | L9: 2022 | M9: 2021 | N9: 2020 | O9: 2019 | P9: 2018
D11: EBIT ($ million) | E11: =Aramco!K11 -> 305087.2 | F11: =Aramco!L11 -> 205844.8 | G11: =Aramco!M11 -> 102229.33 | H11: =Aramco!N11 -> 179965.6 | I11: =Aramco!O11 -> 212908 | K11: EBIT ($ million) | L11: =Exxon!D9 -> 106952 | M11: =Exxon!E9 -> 63206 | N11: =Exxon!F9 -> -398 | O11: =Exxon!G9 -> 52646 | P11: =Exxon!H9 -> 65667
D12: Revenue ($ million) | E12: =Aramco!K9 -> 604366.13 | F12: =Aramco!L9 -> 400468.8 | G12: =Aramco!M9 -> 229890.93 | H12: =Aramco!N9 -> 329809.33 | I12: =Aramco!O9 -> 359204.53 | K12: Revenue ($ million) | L12: =Exxon!D7 -> 413680 | M12: =Exxon!E7 -> 285640 | N12: =Exxon!F7 -> 181502 | O12: =Exxon!G7 -> 264938 | P12: =Exxon!H7 -> 290212
D13: Operating Profit Margin | E13: =E11/E12 -> 0.50480525 | F13: =F11/F12 -> 0.51400958 | G13: =G11/G12 -> 0.44468623 | H13: =H11/H12 -> 0.54566558 | I13: =I11/I12 -> 0.5927208 | K13: Operating Profit Margin | L13: =L11/L12 -> 0.258538 | M13: =M11/M12 -> 0.22127853 | N13: =N11/N12 -> -0.0021928133 | O13: =O11/O12 -> 0.19871064 | P13: =P11/P12 -> 0.22627252
D15: Chevron | K15: Oxy
E17: 2022 | F17: 2021 | G17: 2020 | H17: 2019 | I17: 2018 | L17: 2022 | M17: 2021 | N17: 2020 | O17: 2019 | P17: 2018
D19: EBIT ($ million) | E19: =Chevron!D9 -> 54517 | F19: =Chevron!E9 -> 27002 | G19: =Chevron!F9 -> -3037 | H19: =Chevron!G9 -> 10887 | I19: =Chevron!H9 -> 26750 | K19: EBIT ($ million) | L19: =Oxy!D9 -> 15674 | M19: =Oxy!E9 -> 6029 | N19: =Oxy!F9 -> -2184 | O19: =Oxy!G9 -> 4662 | P19: =Oxy!H9 -> 6666
D20: Revenue ($ million) | E20: =Chevron!D7 -> 246252 | F20: =Chevron!E7 -> 162465 | G20: =Chevron!F7 -> 94692 | H20: =Chevron!G7 -> 146516 | I20: =Chevron!H7 -> 166339 | K20: Revenue ($ million) | L20: =Oxy!D7 -> 37095 | M20: =Oxy!E7 -> 26314 | N20: =Oxy!F7 -> 16261 | O20: =Oxy!G7 -> 21750 | P20: =Oxy!H7 -> 18934
D21: Operating Profit Margin | E21: =E19/E20 -> 0.22138703 | F21: =F19/F20 -> 0.16620195 | G21: =G19/G20 -> -0.032072403 | H21: =H19/H20 -> 0.074305878 | I21: =I19/I20 -> 0.16081616 | K21: Operating Profit Margin | L21: =L19/L20 -> 0.42253673 | M21: =M19/M20 -> 0.22911758 | N21: =N19/N20 -> -0.13430908 | O21: =O19/O20 -> 0.21434483 | P21: =P19/P20 -> 0.35206507
C24: Interest Coverage Ratio
D26: Aramco | K26: Exxon
E28: 2022 | F28: 2021 | G28: 2020 | H28: 2019 | I28: 2018 | L28: 2022 | M28: 2021 | N28: 2020 | O28: 2019 | P28: 2018
D30: EBIT ($ million) | E30: =E11 -> 305087.2 | F30: =F11 -> 205844.8 | G30: =G11 -> 102229.33 | H30: =H11 -> 179965.6 | I30: =I11 -> 212908 | K30: EBIT ($ million) | L30: =L11 -> 106952 | M30: =M11 -> 63206 | N30: =N11 -> -398 | O30: =O11 -> 52646 | P30: =P11 -> 65667
D31: Interest Expense ($ million) | E31: =Aramco!K12 -> 2368.5333 | F31: =Aramco!L12 -> 3215.4667 | G31: =Aramco!M12 -> 2817.0667 | H31: =Aramco!N12 -> 1606.9333 | I31: =Aramco!O12 -> 789.06667 | K31: Interest Expense ($ million) | L31: =Exxon!D10 -> 798 | M31: =Exxon!E10 -> 947 | N31: =Exxon!F10 -> 1158 | O31: =Exxon!G10 -> 830 | P31: =Exxon!H10 -> 766
D32: Interest Coverage Ratio | E32: =E30/E31 -> 128.80849 | F32: =F30/F31 -> 64.017084 | G32: =G30/G31 -> 36.289284 | H32: =H30/H31 -> 111.9932 | I32: =I30/I31 -> 269.82258 | K32: Interest Coverage Ratio | L32: =L30/L31 -> 134.02506 | M32: =M30/M31 -> 66.7434 | N32: =N30/N31 -> -0.34369603 | O32: =O30/O31 -> 63.428916 | P32: =P30/P31 -> 85.727154
D34: Chevron | K34: Oxy
E36: 2022 | F36: 2021 | G36: 2020 | H36: 2019 | I36: 2018 | L36: 2022 | M36: 2021 | N36: 2020 | O36: 2019 | P36: 2018
D38: EBIT ($ million) | E38: =E19 -> 54517 | F38: =F19 -> 27002 | G38: =G19 -> -3037 | H38: =H19 -> 10887 | I38: =I19 -> 26750 | K38: EBIT ($ million) | L38: =L19 -> 15674 | M38: =M19 -> 6029 | N38: =N19 -> -2184 | O38: =O19 -> 4662 | P38: =P19 -> 6666
D39: Interest Expense ($ million) | E39: =Chevron!D10 -> 476 | F39: =Chevron!E10 -> 662 | G39: =Chevron!F10 -> 658 | H39: =Chevron!G10 -> 761 | I39: =Chevron!H10 -> 713 | K39: Interest Expense ($ million) | L39: =Oxy!D10 -> 1030 | M39: =Oxy!E10 -> 1614 | N39: =Oxy!F10 -> 1424 | O39: =Oxy!G10 -> 1066 | P39: =Oxy!H10 -> 389
D40: Interest Coverage Ratio | E40: =E38/E39 -> 114.53151 | F40: =F38/F39 -> 40.78852 | G40: =G38/G39 -> -4.6155015 | H40: =H38/H39 -> 14.306176 | I40: =I38/I39 -> 37.517532 | K40: Interest Coverage Ratio | L40: =L38/L39 -> 15.217476 | M40: =M38/M39 -> 3.7354399 | N40: =N38/N39 -> -1.5337079 | O40: =O38/O39 -> 4.3733583 | P40: =P38/P39 -> 17.136247
C43: Net Debt to EBITDA Ratio
D45: Aramco | K45: Exxon
E47: 2022 | F47: 2021 | G47: 2020 | H47: 2019 | I47: 2018 | L47: 2022 | M47: 2021 | N47: 2020 | O47: 2019 | P47: 2018
D49: Short-Term Debt ($ million) | E49: =Aramco!K20 -> 19937.067 | F49: =Aramco!L20 -> 19880 | G49: =Aramco!M20 -> 26441.867 | H49: =Aramco!N20 -> 6638.6667 | I49: =Aramco!O20 -> 7997.0667 | K49: Short-Term Debt ($ million) | L49: =Exxon!D18 -> 634 | M49: =Exxon!E18 -> 4276 | N49: =Exxon!F18 -> 20458 | O49: =Exxon!G18 -> 20578 | P49: =Exxon!H18 -> 17258
D50: Long-Term Debt ($ million) | E50: =Aramco!K21 -> 84901.333 | F50: =Aramco!L21 -> 116365.6 | G50: =Aramco!M21 -> 116512 | H50: =Aramco!N21 -> 40184 | I50: =Aramco!O21 -> 19021.067 | K50: Long-Term Debt ($ million) | L50: =Exxon!D19 -> 40559 | M50: =Exxon!E19 -> 43428 | N50: =Exxon!F19 -> 47182 | O50: =Exxon!G19 -> 26342 | P50: =Exxon!H19 -> 20538
D51: Cash and Cash Equivalents ($ million) | E51: =Aramco!K16 -> 60279.2 | F51: =Aramco!L16 -> 79887.733 | G51: =Aramco!M16 -> 55261.867 | H51: =Aramco!N16 -> 47388.267 | I51: =Aramco!O16 -> 48840.533 | K51: Cash and Cash Equivalents ($ million) | L51: =Exxon!D14 -> 29640 | M51: =Exxon!E14 -> 6802 | N51: =Exxon!F14 -> 4364 | O51: =Exxon!G14 -> 3089 | P51: =Exxon!H14 -> 3042
D52: Net Debt ($ million) | E52: =E49+E50-E51 -> 44559.2 | F52: =F49+F50-F51 -> 56357.867 | G52: =G49+G50-G51 -> 87692 | H52: =H49+H50-H51 -> -565.6 | I52: =I49+I50-I51 -> -21822.4 | K52: Net Debt ($ million) | L52: =L49+L50-L51 -> 11553 | M52: =M49+M50-M51 -> 40902 | N52: =N49+N50-N51 -> 63276 | O52: =O49+O50-O51 -> 43831 | P52: =P49+P50-P51 -> 34754
D53: EBIT ($ million) | E53: =E11 -> 305087.2 | F53: =F11 -> 205844.8 | G53: =G11 -> 102229.33 | H53: =H11 -> 179965.6 | I53: =I11 -> 212908 | K53: EBIT ($ million) | L53: =L11 -> 106952 | M53: =M11 -> 63206 | N53: =N11 -> -398 | O53: =O11 -> 52646 | P53: =P11 -> 65667
D54: Depreciation and Amortization ($ million) | E54: =Aramco!K10 -> 24431.467 | F54: =Aramco!L10 -> 22805.6 | G54: =Aramco!M10 -> 20322.133 | H54: =Aramco!N10 -> 13404.267 | I54: =Aramco!O10 -> 11022.4 | K54: Depreciation and Amortization ($ million) | L54: =Exxon!D8 -> 24040 | M54: =Exxon!E8 -> 20607 | N54: =Exxon!F8 -> 25756 | O54: =Exxon!G8 -> 18998 | P54: =Exxon!H8 -> 18745
D55: EBITDA ($ million) | E55: =E53+E54 -> 329518.67 | F55: =F53+F54 -> 228650.4 | G55: =G53+G54 -> 122551.47 | H55: =H53+H54 -> 193369.87 | I55: =I53+I54 -> 223930.4 | K55: EBITDA ($ million) | L55: =L53+L54 -> 130992 | M55: =M53+M54 -> 83813 | N55: =N53+N54 -> 25358 | O55: =O53+O54 -> 71644 | P55: =P53+P54 -> 84412
D56: Net Debt to EBITDA Ratio | E56: =E52/E55 -> 0.13522512 | F56: =F52/F55 -> 0.24648051 | G56: =G52/G55 -> 0.71555243 | H56: =H52/H55 -> -0.0029249645 | I56: =I52/I55 -> -0.097451708 | K56: Net Debt to EBITDA Ratio | L56: =L52/L55 -> 0.088196226 | M56: =M52/M55 -> 0.48801499 | N56: =N52/N55 -> 2.4953072 | O56: =O52/O55 -> 0.61178884 | P56: =P52/P55 -> 0.41171871
D58: Chevron | K58: Oxy
E60: 2022 | F60: 2021 | G60: 2020 | H60: 2019 | I60: 2018 | L60: 2022 | M60: 2021 | N60: 2020 | O60: 2019 | P60: 2018
D62: Short-Term Debt ($ million) | E62: =Chevron!D18 -> 1964 | F62: =Chevron!E18 -> 256 | G62: =Chevron!F18 -> 1548 | H62: =Chevron!G18 -> 3282 | I62: =Chevron!H18 -> 5726 | K62: Short-Term Debt ($ million) | L62: =Oxy!D18 -> 165 | M62: =Oxy!E18 -> 186 | N62: =Oxy!F18 -> 440 | O62: =Oxy!G18 -> 51 | P62: =Oxy!H18 -> 116
D63: Long-Term Debt ($ million) | E63: =Chevron!D19 -> 21375 | F63: =Chevron!E19 -> 31113 | G63: =Chevron!F19 -> 42767 | H63: =Chevron!G19 -> 23691 | I63: =Chevron!H19 -> 28733 | K63: Long-Term Debt ($ million) | L63: =Oxy!D19 -> 19670 | M63: =Oxy!E19 -> 29431 | N63: =Oxy!F19 -> 35745 | O63: =Oxy!G19 -> 38537 | P63: =Oxy!H19 -> 10201
D64: Cash and Cash Equivalents ($ million) | E64: =Chevron!D14 -> 17678 | F64: =Chevron!E14 -> 5640 | G64: =Chevron!F14 -> 5596 | H64: =Chevron!G14 -> 5686 | I64: =Chevron!H14 -> 9342 | K64: Cash and Cash Equivalents ($ million) | L64: =Oxy!D14 -> 984 | M64: =Oxy!E14 -> 2764 | N64: =Oxy!F14 -> 2008 | O64: =Oxy!G14 -> 3032 | P64: =Oxy!H14 -> 3033
D65: Net Debt ($ million) | E65: =E62+E63-E64 -> 5661 | F65: =F62+F63-F64 -> 25729 | G65: =G62+G63-G64 -> 38719 | H65: =H62+H63-H64 -> 21287 | I65: =I62+I63-I64 -> 25117 | K65: Net Debt ($ million) | L65: =L62+L63-L64 -> 18851 | M65: =M62+M63-M64 -> 26853 | N65: =N62+N63-N64 -> 34177 | O65: =O62+O63-O64 -> 35556 | P65: =P62+P63-P64 -> 7284
...

Sheet Questions B5 and B6
C3: Valuation of Oxy's Note | K3: Return to TOC
D5: Denomination
D6: Coupon Rate
D7: Frequency of Coupon Payments per Year
D8: Bond Prices
D9: ='Exhibit B4'!D7 -> 42178
D10: 44910
D11: 45019
C13: Question B5: Cash Flows
E15: Coupon | F15: Par Value | G15: Total
D17: 42353
D18: =EDATE(D17,6) -> 42536
D19: =EDATE(D18,6) -> 42719
D20: =EDATE(D19,6) -> 42901
D21: =EDATE(D20,6) -> 43084
D22: =EDATE(D21,6) -> 43266
D23: =EDATE(D22,6) -> 43449
D24: =EDATE(D23,6) -> 43631
D25: =EDATE(D24,6) -> 43814
D26: =EDATE(D25,6) -> 43997
D27: =EDATE(D26,6) -> 44180
D28: =EDATE(D27,6) -> 44362
D29: =EDATE(D28,6) -> 44545
... D36: =EDATE(D35,6) -> 45823
C39: Question B6: Yields to Maturity (YTM)
E41: =D9 -> 42178 | F41: =D10 -> 44910
D43: YTM
D44: Semi-Annual
D45: Annual
D47: =D9 -> 42178
D48: 42353
D49: =EDATE(D48,6) -> 42536
D50: =EDATE(D49,6) -> 42719
D51: =EDATE(D50,6) -> 42901
D52: =EDATE(D51,6) -> 43084
D53: =EDATE(D52,6) -> 43266
D54: =EDATE(D53,6) -> 43449
D55: =EDATE(D54,6) -> 43631
D56: =EDATE(D55,6) -> 43814
D57: =EDATE(D56,6) -> 43997
...

Sheet Question B7
C3: Question B7: Investment Ratios | T3: Return to TOC
C5: Asset Replacement Ratio
D7: Aramco | K7: Exxon
E9: 2022 | F9: 2021 | G9: 2020 | H9: 2019 | I9: 2018 | L9: 2022 | M9: 2021 | N9: 2020 | O9: 2019 | P9: 2018
D11: CapEx ($ million) | K11: CapEx ($ million)
D12: Depreciation and Amortization ($ million) | K12: Depreciation and Amortization ($ million)
D13: Asset Replacement Ratio | K13: Asset Replacement Ratio
D15: Chevron | K15: Oxy
E17: 2022 | F17: 2021 | G17: 2020 | H17: 2019 | I17: 2018 | L17: 2022 | M17: 2021 | N17: 2020 | O17: 2019 | P17: 2018
D19: CapEx ($ million) | K19: CapEx ($ million)
D20: Depreciation and Amortization ($ million) | K20: Depreciation and Amortization ($ million)
D21: Asset Replacement Ratio | K21: Asset Replacement Ratio
C24: Capital Expenditure (CapEx) Intensity
D26: Aramco | K26: Exxon
E28: 2022 | F28: 2021 | G28: 2020 | H28: 2019 | I28: 2018 | L28: 2022 | M28: 2021 | N28: 2020 | O28: 2019 | P28: 2018
D30: CapEx ($ million) | K30: CapEx ($ million)
D31: Revenue ($ million) | K31: Revenue ($ million)
D32: CapEx Intensity | K32: CapEx Intensity
D34: Chevron | K34: Oxy
E36: 2022 | F36: 2021 | G36: 2020 | H36: 2019 | I36: 2018 | L36: 2022 | M36: 2021 | N36: 2020 | O36: 2019 | P36: 2018
D38: CapEx ($ million) | K38: CapEx ($ million)
D39: Revenue ($ million) | K39: Revenue ($ million)
D40: CapEx Intensity | K40: CapEx Intensity

Sheet Question B9
C3: Question B9: Cash Deployment in 2022 | M3: Return to TOC
C5: Residual Cash Flow
F7: Aramco | G7: Chevron | H7: Exxon | I7: Oxy
D9: Cash Flow from Operating Activities ($ millions)
D11: Capital Expenditure ($ million)
D12: Dividends ($ million)
D13: Share Buybacks ($ million)
D14: Net Repayments of Debt ($ million)
D15: Cash Uses ($ million)
D17: Residual Cash Flow ($ million)
C20: Cash Uses Allocation
F22: Aramco | G22: Chevron | H22: Exxon | I22: Oxy
D24: Capital Expenditure ($ million)
D25: Dividends ($ million)
D26: Share Buybacks ($ million)
D27: Net Repayments of Debt ($ million)
D28: Cash Uses ($ million)
