Workbook

Sheet Table of Content
C3: Table of Content
C5: Data
C6: Exhibit 3: Sanofi's Earnings per Share and Dividend per Share
C7: Exhibit 4: Sanofi's Debt
C8: Appendix 1: Sanofi's Selected Financial Data and Ratios
C9: Appendix 2: Selected Country and Market Data
C10: Appendix 3: Sanofi's and Selected Competitors' Risk Measures
C12: Case Questions
C13: Questions 2 and 4: Sanofi's Value and Cost of Equity
C14: Questions 3 and 4: Sanofi's Value and Cost of Debt
C15: Question 6: Sanofi's Weighted Average Cost of Capital (WACC)

Sheet Exhibit 3
C3: Exhibit 3: Sanofi's Earnings per Share and Dividend per Share | J3: Return to TOC
C5: Year | D5: Earnings per Share (EPS) | E5: Growth Rate in EPS | F5: Dividend Per Share (DPS) | G5: Growth Rate in DPS
C6: 2023 | D6: 4.31 | E6: =(D6-D7)/D7 -> -0.35575486 | F6: 3.76 | G6: =(F6-F7)/F7 -> 0.056179775
C7: 2022 | D7: 6.69 | E7: =(D7-D8)/D8 -> 0.34607646 | F7: 3.56 | G7: =(F7-F8)/F8 -> 0.069069069
C8: 2021 | D8: 4.97 | E8: =(D8-D9)/D9 -> -0.49337411 | F8: 3.33 | G8: =(F8-F9)/F9 -> 0.040625
C9: 2020 | D9: 9.81 | E9: =(D9-D10)/D10 -> 3.3794643 | F9: 3.2 | G9: =(F9-F10)/F10 -> 0.015873016
C10: 2019 | D10: 2.24 | E10: =(D10-D11)/D11 -> -0.35072464 | F10: 3.15 | G10: =(F10-F11)/F11 -> 0.026058632
C11: 2018 | D11: 3.45 | E11: =(D11-D12)/D12 -> -0.48507463 | F11: 3.07 | G11: =(F11-F12)/F12 -> 0.01320132
C12: 2017 | D12: 6.7 | E12: =(D12-D13)/D13 -> 0.83060109 | F12: 3.03 | G12: =(F12-F13)/F13 -> 0.023648649
C13: 2016 | D13: 3.66 | E13: =(D13-D14)/D14 -> 0.11585366 | F13: 2.96 | G13: =(F13-F14)/F14 -> 0.010238908
C14: 2015 | D14: 3.28 | E14: =(D14-D15)/D15 -> -0.017964072 | F14: 2.93 | G14: =(F14-F15)/F15 -> 0.028070175
C15: 2014 | D15: 3.34 | E15: =(D15-D16)/D16 -> 0.1886121 | F15: 2.85 | G15: =(F15-F16)/F16 -> 0.017857143
C16: 2013 | D16: 2.81 | E16: =(D16-D17)/D17 -> -0.2425876 | F16: 2.8 | G16: =(F16-F17)/F17 -> 0.010830325
C17: 2012 | D17: 3.71 | E17: =(D17-D18)/D18 -> -0.13921114 | F17: 2.77 | G17: =(F17-F18)/F18 -> 0.045283019
... C19: 2010 | D19: 4.19 | E19: =(D19-D20)/D20 -> 0.039702233 | F19: 2.5 | G19: =(F19-F20)/F20 -> 0.041666667
C20: 2009 | D20: 4.03 | E20: 0.112 | F20: 2.4 | G20: 0.0909

Sheet Exhibit 4
C3: Exhibit 4: Sanofi's Debt | K3: Return to TOC
C5: Euro Medium Term Note (EMTN) Program
C7: ISIN Code | D7: Issuance Date | E7: Maturity Date | F7: Outstanding Amount (million) | G7: Coupon Rate | H7: Yield to Maturity (YTM)
C8: FR0013143997 | D8: 42465 | E8: 45387 | F8: 600 | G8: 0.00625 | H8: 0.02257
C9: FR0013505104 | D9: 43920 | E9: 45748 | F9: 1000 | G9: 0.01 | H9: 0.03485
C10: FR0014009KS6 | D10: 44657 | E10: 45753 | F10: 850 | G10: 0.00875 | H10: 0.0334
C11: FR0012969038 | D11: 42269 | E11: 45922 | F11: 750 | G11: 0.015 | H11: 0.03057
C12: FR0013324340 | D12: 43180 | E12: 46102 | F12: 1500 | G12: 0.01 | H12: 0.02892
C13: FR0012146801 | D13: 41892 | E13: 46275 | F13: 1510 | G13: 0.0175 | H13: 0.0288
C14: FR0013201639 | D14: 42626 | E14: 46400 | F14: 1150 | G14: 0.005 | H14: 0.02788
C15: FR0013144003 | D15: 42465 | E15: 46848 | F15: 700 | G15: 0.01125 | H15: 0.02757
C16: FR0013409844 | D16: 43545 | E16: 47198 | F16: 650 | G16: 0.00875 | H16: 0.02673
C17: FR0014009KQ0 | D17: 44657 | E17: 47214 | F17: 650 | G17: 0.0125 | H17: 0.02781
C18: FR0013324357 | D18: 43180 | E18: 47563 | F18: 2000 | G18: 0.01375 | H18: 0.02856
C19: FR0013505112 | D19: 43920 | E19: 47574 | F19: 1000 | G19: 0.015 | H19: 0.0281
... C21: FR0013324373 | D21: 43180 | E21: 50485 | F21: 1250 | G21: 0.01875 | H21: 0.03007
F22: =SUM(F8:F21) -> 14110
C24: U.S. Public Bond Issue Program
C26: ISIN Code | D26: Issuance Date | E26: Maturity Date | F26: Outstanding Amount (million) | G26: Coupon Rate | H26: Yield to Maturity (YTM)
C27: US801060AD60 | D27: 43270 | E27: 46923 | F27: 1000 | G27: 0.03625 | H27: 0.04032
C29: Commercial Paper (CP) Programs
C31: Type | D31: Maximum Drawdown (million) | E31: Outstanding Amount (million)
C32: Negotiable European CP Program | D32: 6000 | E32: 40
C33: U.S. CP Program | D33: 10000 | E33: 1000
C35: Bank Borrowings
C37: Type | D37: Maximum Drawdown (million) | E37: Outstanding Amount (million)
C38: Term Loans | E38: =1248+203 -> 1451
C39: Syndicated Credit Facilities | D39: 8000 | E39: 0

Sheet Appendix 1
C3: Appendix 1: Sanofi's Selected Financial Data and Ratios | I3: Return to TOC
C5: Income Statements (million EUR)
D7: 2023 | E7: 2022 | F7: 2021
C8: Sales | D8: 43070 | E8: 42997 | F8: 37761
C9: Gross Profit | D9: 32208 | E9: 31694 | F9: 26920
C10: Operating Income | D10: 7875 | E10: 10656 | F10: 8126
C11: Interest Expense | D11: -1313 | E11: -440 | F11: -368
C12: Interest Income | D12: 591 | E12: 206 | F12: 40
C13: Income Before Tax | D13: =SUM(D10:D12) -> 7153 | E13: =SUM(E10:E12) -> 10422 | F13: =SUM(F10:F12) -> 7798
C14: Income Tax | D14: -1602 | E14: -2006 | F14: -1558
C15: Share of Profit/(Loss) from Investments | D15: -115 | E15: 68 | F15: 39
C16: Net Income | D16: =SUM(D13:D15) -> 5436 | E16: =SUM(E13:E15) -> 8484 | F16: =SUM(F13:F15) -> 6279
C17: Non-Controlling Interest | D17: 36 | E17: 113 | F17: 56
C18: Attributabe to Sanofi's Shareholders | D18: =D16-D17 -> 5400 | E18: =E16-E17 -> 8371 | F18: =F16-F17 -> 6223
C20: Managerial Balance Sheets (million EUR)
D22: 2023 | E22: 2022 | F22: 2021
C24: Cash and Cash Equivalents | D24: 8710 | E24: 12736 | F24: 10098
C25: Net Working Capital | D25: 14632 | E25: 14562 | F25: 14375
C26: Net Fixed Assets | D26: 95794 | E26: 92611 | F26: 89589
C27: Invested Capital | D27: =SUM(D24:D26) -> 119136 | E27: =SUM(E24:E26) -> 119909 | F27: =SUM(F24:F26) -> 114062
C29: Short-Term Debt and Current Portion of Long-Term Debt | D29: 2045 | E29: 4174 | F29: 3183
C30: Long-Term Debt | D30: 14347 | E30: 14857 | F30: 17123
C31: Interest-Bearing Debt | D31: =SUM(D29:D30) -> 16392 | E31: =SUM(E29:E30) -> 19031 | F31: =SUM(F29:F30) -> 20306
C32: Other Liabilities | D32: 28391 | E32: 25726 | F32: 24725
C33: Shareholders' Equity | D33: 74353 | E33: 75152 | F33: 69031
C34: Non-Controlling Interest | D34: 313 | E34: 368 | F34: 350
C35: Attributabe to Sanofi's Shareholders | D35: =D33-D34 -> 74040 | E35: =E33-E34 -> 74784 | F35: =F33-F34 -> 68681
C36: Capital Employed | D36: =SUM(D31:D33) -> 119136 | E36: =SUM(E31:E33) -> 119909 | F36: =SUM(F31:F33) -> 114062
C38: Cash Flow Statements (million EUR)
D40: 2023 | E40: 2022 | F40: 2021
C42: Cash Flow from Operating Activities | D42: 10258 | E42: 10526 | F42: 10522
C43: Cash Flow from Investing Activities | D43: -6200 | E43: -2075 | F43: -7298
C44: Cash Flow from Financing Activities | D44: 8052 | E44: -5821 | F44: -7056
C45: Impact of Exchange Rates on Cash and Cash Equivalents | D45: -32 | E45: 8 | F45: 15
C46: Net Change in Cash and Cash Equivalents | D46: =SUM(D42:D45) -> 12078 | E46: =SUM(E42:E45) -> 2638 | F46: =SUM(F42:F45) -> -3817
C48: Modified DuPont Model
D50: 2023 | E50: 2022 | F50: 2021
C52: Growth Rate in Sales | D52: =(D8-E8)/E8 -> 0.0016977929 | E52: =(E8-F8)/F8 -> 0.13866158 | F52: 0.047723426
C54: Operating Profit Margin | D54: =D10/D8 -> 0.18284189 | E54: =E10/E8 -> 0.24783124 | F54: =F10/F8 -> 0.21519557
C55: Capital Turnover | D55: =D8/D27 -> 0.36151961 | E55: =E8/E27 -> 0.35858026 | F55: =F8/F27 -> 0.33105679
...

Sheet Appendix 2
C3: Appendix 2: Selected Country and Market Data | L3: Return to TOC
C5: Corporate Income Tax Rates
C6: France | D6: 0.25
C7: U.S.
C8: Federal | D8: 0.21
C9: State, Low | D9: 0
C10: State, High | D10: 0.12
C12: Equity Risk Premium
C13: France | D13: 0.0532
C14: U.S. | D14: 0.046
C16: Spot Exchange Rate
C17: USD/EUR | D17: 1.084
C19: French Treasury Securities
C21: Maturity | D21: Yield to Maturity
C22: 1 month | D22: 0.03835
C23: 3 month | D23: 0.03856
C24: 6 month | D24: 0.03791
C25: 9 month | D25: 0.03668
C26: 1 year | D26: 0.03539
C27: 2 years | D27: 0.0297
C28: 3 years | D28: 0.02786
C29: 4 years | D29: 0.02722
C30: 5 years | D30: 0.02726
C31: 6 years | D31: 0.02696
C32: 7 years | D32: 0.027193
C33: 8 years | D33: 0.02755
... C39: 30 years | D39: 0.03327
C41: Credit Spreads
C43: Maturity | D43: AAA/Aaa | E43: AA/Aa2 | F43: A/A2 | G43: BBB/Baa2 | H43: BB/Ba2 | I43: B/B2
C44: 3 month | D44: 0.0013 | E44: 0.0023 | F44: 0.0031 | G44: 0.0045 | H44: 0.0179 | I44: 0.025
C45: 6 month | D45: 0.0007 | E45: 0.0017 | F45: 0.0025 | G45: 0.0039 | H45: 0.0177 | I45: 0.0251
C46: 1 year | D46: 0.0008 | E46: 0.0017 | F46: 0.0026 | G46: 0.004 | H46: 0.0186 | I46: 0.0267
C47: 2 years | D47: 0.0017 | E47: 0.0026 | F47: 0.0035 | G47: 0.0049 | H47: 0.021 | I47: 0.0304
C48: 3 years | D48: 0.0029 | E48: 0.0038 | F48: 0.0047 | G48: 0.0061 | H48: 0.0236 | I48: 0.0343
C49: 5 years | D49: 0.0054 | E49: 0.0064 | F49: 0.0073 | G49: 0.0086 | H49: 0.0287 | I49: 0.0417
C50: 7 years | D50: 0.0061 | E50: 0.0071 | F50: 0.008 | G50: 0.0094 | H50: 0.0316 | I50: 0.0467
C51: 10 years | D51: 0.009 | E51: 0.0099 | F51: 0.0108 | G51: 0.0122 | H51: 0.0372 | I51: 0.0547
C52: 20 years | D52: 0.0139 | E52: 0.0148 | F52: 0.0157 | G52: 0.0171 | H52: 0.0469 | I52: 0.0688
C53: 30 years | D53: 0.0112 | E53: 0.0122 | F53: 0.0131 | G53: 0.0145 | H53: 0.0452 | I53: 0.0678

Sheet Appendix 3
C3: Appendix 3: Sanofi's and Selected Competitors' Risk Measures | H3: Return to TOC
C5: Company | D5: Volatility | E5: Beta
C6: Amgen | D6: 0.24 | E6: 0.72
C7: AstraZeneca | D7: 0.22 | E7: 1.06
C8: Eli Lilly | D8: 0.31 | E8: 0.96
C9: Johnson & Johnson | D9: 0.16 | E9: 0.12
C10: Merck | D10: 0.2 | E10: 0.21
C11: Novartis | D11: 0.17 | E11: 0.92
C12: Novo Nordisk | D12: 0.31 | E12: 1.34
C13: Pfizer | D13: 0.24 | E13: 0.27
C14: Roche | D14: 0.19 | E14: 0.98
C15: Sanofi | D15: 0.25 | E15: 0.61

Sheet Equity
C3: Questions 2 and 4: Sanofi's Value and Cost of Equity | G3: Return to TOC
C5: Value of Equity (million EUR)
C7: Shareholders' Equity | D7: ='Appendix 1'!D33 -> 74353
C9: Stock Price (EUR) | D9: 93.36
C10: Shares Outstanding (million) | D10: 1265
C11: Market Capitalization | D11: =D9*D10 -> 118100.4
C13: Cost of Equity Using the Dividend Discount Model (DDM)
C15: Dividend per Share (EUR) | D15: ='Exhibit 3'!F6 -> 3.76
C16: Stock Price (EUR) | D16: =D9 -> 93.36
C17: Dividend Yield | D17: =D15/D16 -> 0.040274207
C18: Average Growth Rate in Dividends | D18: =AVERAGE('Exhibit 3'!G6:G20) -> 0.036633447
C19: Cost of Equity | D19: =D17+D18 -> 0.076907654
C21: Cost of Equity Using the Capital Asset Pricing Model (CAPM)
C23: Risk-Free Rate | D23: ='Appendix 2'!D39 -> 0.03327
C24: Beta | D24: ='Appendix 3'!E15 -> 0.61
C25: Equity Risk Premium | D25: ='Appendix 2'!D13 -> 0.0532
C26: Cost of Equity | D26: =D23+D24*D25 -> 0.065722

Sheet Debt
C3: Questions 3 and 4: Sanofi's Value and Cost of Debt | G3: Return to TOC
C5: Value of Debt (million EUR)
C7: Interest-Bearing Debt | D7: ='Appendix 1'!D31 -> 16392
C9: Amount of Debt Outstanding | D9: ='Exhibit 4'!F22+'Exhibit 4'!F27/'Appendix 2'!D17+'Exhibit 4'!E32+'Exhibit 4'!E33/'Appendix 2'!D17+'Exhibit 4'!E38+'Exhibit 4'!E39 -> 17446.018
C11: Cost of Debt using the Spread to Treasury Method
C13: Pre-Tax Cost of Debt | D13: ='Appendix 2'!D39+'Appendix 2'!E53 -> 0.04547
C14: Effective Tax Rate | D14: =1-'Appendix 1'!D60 -> 0.245072
C15: After-Tax Cost of Debt | D15: =D13*(1-D14) -> 0.034326576

Sheet WACC
C3: Question 6: Sanofi's Weighted Average Cost of Capital (WACC) | K3: Return to TOC
C5: Calculation of the WACC
D7: Value (million EUR) | E7: Weight | F7: After-Tax Cost
C8: Debt | D8: =Debt!D9 -> 17446.018 | E8: =D8/$D$10 -> 0.12870881 | F8: =Debt!D15 -> 0.034326576
C9: Equity | D9: =Equity!D11 -> 118100.4 | E9: =D9/$D$10 -> 0.87129119 | F9: =Equity!D26 -> 0.065722
C10: Total | D10: =SUM(D8:D9) -> 135546.42
C12: WACC | D12: =E8*F8+E9*F9 -> 0.061681132
C14: Sensitivity Analysis
C16: Beta | D16: 0.61
C17: Credit Spread | D17: 0.0122
C19: P-T CoD | D19: ='Appendix 2'!D39+WACC!D17 -> 0.04547
C20: ETR | D20: =1-'Appendix 1'!D60 -> 0.245072
C21: A-T CoD | D21: =D19*(1-D20) -> 0.034326576
C23: RFR | D23: ='Appendix 2'!D39 -> 0.03327
C24: Beta | D24: =D16 -> 0.61
C25: ERP | D25: ='Appendix 2'!D13 -> 0.0532
C26: CoE | D26: =D23+D24*D25 -> 0.065722
D28: Value (million EUR) | E28: Weight | F28: After-Tax Cost
C29: Debt | D29: =Debt!D9 -> 17446.018 | E29: =D29/$D$10 -> 0.12870881 | F29: =D21 -> 0.034326576
C30: Equity | D30: =Equity!D11 -> 118100.4 | E30: =D30/$D$10 -> 0.87129119 | F30: =D26 -> 0.065722
C31: Total | D31: =SUM(D29:D30) -> 135546.42
C33: WACC | D33: =E29*F29+E30*F30 -> 0.061681132
E35: Credit Spread
D36: =D33 -> 0.061681132 | E36: 0.0122 | F36: 0.0132 | G36: 0.0142 | H36: 0.0152
C37: Beta | D37: 0.61 | E37: 0.061681132 | F37: 0.061778298 | G37: 0.061875464 | H37: 0.06197263
D38: 0.71 | E38: 0.066316401 | F38: 0.066413567 | G38: 0.066510733 | H38: 0.066607899
D39: 0.81 | E39: 0.070951671 | F39: 0.071048836 | G39: 0.071146002 | H39: 0.071243168
D40: 0.91 | E40: 0.07558694 | F40: 0.075684106 | G40: 0.075781271 | H40: 0.075878437
D41: 1.01 | E41: 0.080222209 | F41: 0.080319375 | G41: 0.080416541 | H41: 0.080513706
D42: 1.11 | E42: 0.084857478 | F42: 0.084954644 | G42: 0.08505181 | H42: 0.085148976
D43: 1.21 | E43: 0.089492747 | F43: 0.089589913 | G43: 0.089687079 | H43: 0.089784245
D44: 1.31 | E44: 0.094128016 | F44: 0.094225182 | G44: 0.094322348 | H44: 0.094419514
